mplus_output/uni-02-HRS_CODA_DTS_W6.out
Mplus VERSION 8.1 (Mac)
MUTHEN & MUTHEN
04/23/2020  10:56 PM

INPUT INSTRUCTIONS

  DATA:
  FILE = "uni-02-HRS_CODA_DTS_W6.dat";

  VARIABLE:
  NAMES = mplusid UDTS UDAY UIWR UDWR USUB UBAK UNM1 UNM2 UNM5 UNM6;
   MISSING=.;
   CATEGORICAL ARE all; idvariable = mplusid;
  ANALYSIS:
  estimator = wlsmv; coverage=0;
  MODEL:
  g by UDAY * ;
   g by UIWR * ;
   g by UDWR * ;
   g by USUB * ;
   g by UBAK * ;
   g by UNM1 * ;
   g by UNM2 * ;
   g by UNM5 * ;
   g by UNM6 * ;
   g by UDTS * ;
   g @ 1;

  OUTPUT:
  standardized; svalues;



*** WARNING
  Data set contains cases with missing on all variables.
  These cases were not included in the analysis.
  Number of cases with missing on all variables:  134
   1 WARNING(S) FOUND IN THE INPUT INSTRUCTIONS




SUMMARY OF ANALYSIS

Number of groups                                                 1
Number of observations                                        2186

Number of dependent variables                                   10
Number of independent variables                                  0
Number of continuous latent variables                            1

Observed dependent variables

  Binary and ordered categorical (ordinal)
   UDTS        UDAY        UIWR        UDWR        USUB        UBAK
   UNM1        UNM2        UNM5        UNM6

Continuous latent variables
   G

Variables with special functions

  ID variable           MPLUSID

Estimator                                                    WLSMV
Maximum number of iterations                                  1000
Convergence criterion                                    0.500D-04
Maximum number of steepest descent iterations                   20
Maximum number of iterations for H1                           2000
Convergence criterion for H1                             0.100D-03
Parameterization                                             DELTA
Link                                                        PROBIT

Input data file(s)
  uni-02-HRS_CODA_DTS_W6.dat

Input data format  FREE


SUMMARY OF DATA

     Number of missing data patterns            40


COVARIANCE COVERAGE OF DATA

Minimum covariance coverage value   0.000


     PROPORTION OF DATA PRESENT


           Covariance Coverage
              UDTS          UDAY          UIWR          UDWR          USUB
              ________      ________      ________      ________      ________
 UDTS           0.998
 UDAY           0.998         1.000
 UIWR           0.985         0.986         0.986
 UDWR           0.911         0.912         0.912         0.912
 USUB           0.902         0.903         0.898         0.841         0.903
 UBAK           0.989         0.991         0.980         0.907         0.901
 UNM1           0.997         0.998         0.985         0.911         0.903
 UNM2           0.984         0.985         0.973         0.900         0.895
 UNM5           0.992         0.994         0.981         0.907         0.899
 UNM6           0.972         0.973         0.961         0.890         0.887


           Covariance Coverage
              UBAK          UNM1          UNM2          UNM5          UNM6
              ________      ________      ________      ________      ________
 UBAK           0.991
 UNM1           0.991         0.998
 UNM2           0.978         0.985         0.985
 UNM5           0.985         0.992         0.981         0.994
 UNM6           0.965         0.972         0.963         0.973         0.973


UNIVARIATE PROPORTIONS AND COUNTS FOR CATEGORICAL VARIABLES

    UDTS
      Category 1    0.003            7.000
      Category 2    0.016           36.000
      Category 3    0.158          345.000
      Category 4    0.822         1794.000
    UDAY
      Category 1    0.019           41.000
      Category 2    0.981         2145.000
    UIWR
      Category 1    0.000            1.000
      Category 2    0.008           18.000
      Category 3    0.028           61.000
      Category 4    0.077          167.000
      Category 5    0.155          333.000
      Category 6    0.502         1082.000
      Category 7    0.146          314.000
      Category 8    0.057          122.000
      Category 9    0.020           43.000
      Category 10    0.006           14.000
    UDWR
      Category 1    0.003            5.000
      Category 2    0.041           82.000
      Category 3    0.088          176.000
      Category 4    0.161          320.000
      Category 5    0.220          439.000
      Category 6    0.378          754.000
      Category 7    0.072          144.000
      Category 8    0.022           43.000
      Category 9    0.010           20.000
      Category 10    0.005           10.000
    USUB
      Category 1    0.036           71.000
      Category 2    0.081          159.000
      Category 3    0.089          176.000
      Category 4    0.127          251.000
      Category 5    0.203          400.000
      Category 6    0.464          916.000
    UBAK
      Category 1    0.043           93.000
      Category 2    0.957         2073.000
    UNM1
      Category 1    0.007           16.000
      Category 2    0.993         2166.000
    UNM2
      Category 1    0.058          126.000
      Category 2    0.942         2028.000
    UNM5
      Category 1    0.023           50.000
      Category 2    0.977         2122.000
    UNM6
      Category 1    0.108          230.000
      Category 2    0.892         1898.000



THE MODEL ESTIMATION TERMINATED NORMALLY



MODEL FIT INFORMATION

Number of Free Parameters                       42

Chi-Square Test of Model Fit

          Value                            299.612*
          Degrees of Freedom                    35
          P-Value                           0.0000

*   The chi-square value for MLM, MLMV, MLR, ULSMV, WLSM and WLSMV cannot be used
    for chi-square difference testing in the regular way.  MLM, MLR and WLSM
    chi-square difference testing is described on the Mplus website.  MLMV, WLSMV,
    and ULSMV difference testing is done using the DIFFTEST option.

RMSEA (Root Mean Square Error Of Approximation)

          Estimate                           0.059
          90 Percent C.I.                    0.053  0.065
          Probability RMSEA <= .05           0.009

CFI/TLI

          CFI                                0.968
          TLI                                0.958

Chi-Square Test of Model Fit for the Baseline Model

          Value                           8242.300
          Degrees of Freedom                    45
          P-Value                           0.0000

SRMR (Standardized Root Mean Square Residual)

          Value                              0.094

Optimum Function Value for Weighted Least-Squares Estimator

          Value                     0.61132849D-01



MODEL RESULTS

                                                    Two-Tailed
                    Estimate       S.E.  Est./S.E.    P-Value

 G        BY
    UDAY               0.587      0.067      8.790      0.000
    UIWR               0.870      0.017     50.404      0.000
    UDWR               0.865      0.018     48.662      0.000
    USUB               0.365      0.024     15.488      0.000
    UBAK               0.431      0.045      9.661      0.000
    UNM1               0.311      0.100      3.103      0.002
    UNM2               0.523      0.037     14.165      0.000
    UNM5               0.667      0.060     11.037      0.000
    UNM6               0.509      0.032     15.816      0.000
    UDTS               0.370      0.028     12.999      0.000

 Thresholds
    UDTS$1            -2.726      0.125    -21.882      0.000
    UDTS$2            -2.060      0.062    -33.101      0.000
    UDTS$3            -0.924      0.031    -29.385      0.000
    UDAY$1            -2.080      0.063    -32.868      0.000
    UIWR$1            -3.311      0.280    -11.838      0.000
    UIWR$2            -2.373      0.084    -28.134      0.000
    UIWR$3            -1.785      0.050    -35.541      0.000
